<robot
  name="MRA7 - URDF2.SLDASM">
  <link
    name="base_link">
    <inertial>
      <origin
        xyz="-0.00032958 4.2936E-07 0.043799"
        rpy="0 0 0" />
      <mass
        value="0.47411" />
      <inertia
        ixx="0.0010382"
        ixy="-8.6316E-09"
        ixz="-3.8513E-06"
        iyy="0.0010308"
        iyz="3.9048E-09"
        izz="0.0011268" />
    </inertial>
    <visual>
      <origin
        xyz="0 0 0"
        rpy="0 0 0" />
      <geometry>
        <mesh
          filename="package://MRA7 - URDF2.SLDASM/meshes/base_link.stl" />
      </geometry>
      <material
        name="">
        <color
          rgba="0.6 0.6 0.6 1" />
      </material>
    </visual>
    <collision>
      <origin
        xyz="0 0 0"
        rpy="0 0 0" />
      <geometry>
        <mesh
          filename="package://MRA7 - URDF2.SLDASM/meshes/base_link.stl" />
      </geometry>
    </collision>
  </link>
  <link
    name="1_Link">
    <inertial>
      <origin
        xyz="-5.508E-05 -0.013306 -0.048516"
        rpy="0 0 0" />
      <mass
        value="0.49999" />
      <inertia
        ixx="0.0019977"
        ixy="5.35E-08"
        ixz="7.7321E-07"
        iyy="0.0020764"
        iyz="0.00012166"
        izz="0.0009413" />
    </inertial>
    <visual>
      <origin
        xyz="0 0 0"
        rpy="0 0 0" />
      <geometry>
        <mesh
          filename="package://MRA7 - URDF2.SLDASM/meshes/1_Link.stl" />
      </geometry>
      <material
        name="">
        <color
          rgba="0.6 0.6 0.6 1" />
      </material>
    </visual>
    <collision>
      <origin
        xyz="0 0 0"
        rpy="0 0 0" />
      <geometry>
        <mesh
          filename="package://MRA7 - URDF2.SLDASM/meshes/1_Link.stl" />
      </geometry>
    </collision>
  </link>
  <joint
    name="1_Joint"
    type="revolute">
    <origin
      xyz="0 0 0.234"
      rpy="0 0 0" />
    <parent
      link="base_link" />
    <child
      link="1_Link" />
    <axis
      xyz="0 0 1" />
    <limit
      lower="-3.14"
      upper="3.14"
      effort="40"
      velocity="1.3" />
    <calibration
      rising="0"
      falling="0" />
    <dynamics
      damping="0"
      friction="0" />
    <safety_controller
      soft_upper="0"
      soft_lower="0"
      k_position="0"
      k_velocity="0" />
  </joint>
  <link
    name="2_Link">
    <inertial>
      <origin
        xyz="-6.6364E-06 -0.069213 0.028907"
        rpy="0 0 0" />
      <mass
        value="0.46648" />
      <inertia
        ixx="0.0023348"
        ixy="2.2987E-07"
        ixz="5.9399E-08"
        iyy="0.00088621"
        iyz="-0.00058578"
        izz="0.0022334" />
    </inertial>
    <visual>
      <origin
        xyz="0 0 0"
        rpy="0 0 0" />
      <geometry>
        <mesh
          filename="package://MRA7 - URDF2.SLDASM/meshes/2_Link.stl" />
      </geometry>
      <material
        name="">
        <color
          rgba="0.6 0.6 0.6 1" />
      </material>
    </visual>
    <collision>
      <origin
        xyz="0 0 0"
        rpy="0 0 0" />
      <geometry>
        <mesh
          filename="package://MRA7 - URDF2.SLDASM/meshes/2_Link.stl" />
      </geometry>
    </collision>
  </link>
  <joint
    name="2_Joint"
    type="revolute">
    <origin
      xyz="0 0 0"
      rpy="-1.5708 0 0" />
    <parent
      link="1_Link" />
    <child
      link="2_Link" />
    <axis
      xyz="0 0 1" />
    <limit
      lower="-2.35"
      upper="2.35"
      effort="40"
      velocity="1.3" />
    <calibration
      rising="0"
      falling="0" />
    <dynamics
      damping="0"
      friction="0" />
    <safety_controller
      soft_upper="0"
      soft_lower="0"
      k_position="0"
      k_velocity="0" />
  </joint>
  <link
    name="3_Link">
    <inertial>
      <origin
        xyz="-1.5849E-05 -0.01354 -0.04457"
        rpy="0 0 0" />
      <mass
        value="0.3899" />
      <inertia
        ixx="0.0013471"
        ixy="1.5771E-07"
        ixz="3.9954E-07"
        iyy="0.0013595"
        iyz="6.3297E-05"
        izz="0.00055466" />
    </inertial>
    <visual>
      <origin
        xyz="0 0 0"
        rpy="0 0 0" />
      <geometry>
        <mesh
          filename="package://MRA7 - URDF2.SLDASM/meshes/3_Link.stl" />
      </geometry>
      <material
        name="">
        <color
          rgba="0.6 0.6 0.6 1" />
      </material>
    </visual>
    <collision>
      <origin
        xyz="0 0 0"
        rpy="0 0 0" />
      <geometry>
        <mesh
          filename="package://MRA7 - URDF2.SLDASM/meshes/3_Link.stl" />
      </geometry>
    </collision>
  </link>
  <joint
    name="3_Joint"
    type="revolute">
    <origin
      xyz="0 -0.292 0"
      rpy="1.5708 0 0" />
    <parent
      link="2_Link" />
    <child
      link="3_Link" />
    <axis
      xyz="0 0 1" />
    <limit
      lower="-3.14"
      upper="3.14"
      effort="24"
      velocity="1.3" />
    <calibration
      rising="0"
      falling="0" />
    <dynamics
      damping="0"
      friction="0" />
    <safety_controller
      soft_upper="0"
      soft_lower="0"
      k_position="0"
      k_velocity="0" />
  </joint>
  <link
    name="4_Link">
    <inertial>
      <origin
        xyz="-1.6497E-05 -0.067843 0.02549"
        rpy="0 0 0" />
      <mass
        value="0.31965" />
      <inertia
        ixx="0.0013995"
        ixy="2.3243E-07"
        ixz="2.0838E-07"
        iyy="0.00051411"
        iyz="-0.00035142"
        izz="0.0013457" />
    </inertial>
    <visual>
      <origin
        xyz="0 0 0"
        rpy="0 0 0" />
      <geometry>
        <mesh
          filename="package://MRA7 - URDF2.SLDASM/meshes/4_Link.stl" />
      </geometry>
      <material
        name="">
        <color
          rgba="0.6 0.6 0.6 1" />
      </material>
    </visual>
    <collision>
      <origin
        xyz="0 0 0"
        rpy="0 0 0" />
      <geometry>
        <mesh
          filename="package://MRA7 - URDF2.SLDASM/meshes/4_Link.stl" />
      </geometry>
    </collision>
  </link>
  <joint
    name="4_Joint"
    type="revolute">
    <origin
      xyz="0 0 0"
      rpy="-1.5708 0 0" />
    <parent
      link="3_Link" />
    <child
      link="4_Link" />
    <axis
      xyz="0 0 1" />
    <limit
      lower="-2.35"
      upper="2.35"
      effort="24"
      velocity="1.3" />
    <calibration
      rising="0"
      falling="0" />
    <dynamics
      damping="0"
      friction="0" />
    <safety_controller
      soft_upper="0"
      soft_lower="0"
      k_position="0"
      k_velocity="0" />
  </joint>
  <link
    name="5_Link">
    <inertial>
      <origin
        xyz="-2.9284002488612E-05 -0.0103047281193087 -0.0397405175022244"
        rpy="0 0 0" />
      <mass
        value="0.223438457099327" />
      <inertia
        ixx="0.000470145043424596"
        ixy="-1.48410185235443E-07"
        ixz="-8.55051868197896E-08"
        iyy="0.000465483933370723"
        iyz="5.61285589273483E-05"
        izz="0.00027289857508905" />
    </inertial>
    <visual>
      <origin
        xyz="0 0 0"
        rpy="0 0 0" />
      <geometry>
        <mesh
          filename="package://MRA7 - URDF2.SLDASM/meshes/5_Link.stl" />
      </geometry>
      <material
        name="">
        <color
          rgba="0.6 0.6 0.6 1" />
      </material>
    </visual>
    <collision>
      <origin
        xyz="0 0 0"
        rpy="0 0 0" />
      <geometry>
        <mesh
          filename="package://MRA7 - URDF2.SLDASM/meshes/5_Link.stl" />
      </geometry>
    </collision>
  </link>
  <joint
    name="5_Joint"
    type="revolute">
    <origin
      xyz="0 -0.242 0"
      rpy="1.5708 0 0" />
    <parent
      link="4_Link" />
    <child
      link="5_Link" />
    <axis
      xyz="0 0 1" />
    <limit
      lower="-3.14"
      upper="3.14"
      effort="20"
      velocity="1.57" />
    <calibration
      rising="0"
      falling="0" />
    <dynamics
      damping="0"
      friction="0" />
    <safety_controller
      soft_upper="0"
      soft_lower="0"
      k_position="0"
      k_velocity="0" />
  </joint>
  <link
    name="6_Link">
    <inertial>
      <origin
        xyz="6.1601E-05 -0.046649 0.014044"
        rpy="0 0 0" />
      <mass
        value="0.159" />
      <inertia
        ixx="0.00035565"
        ixy="3.4159E-07"
        ixz="2.2922E-07"
        iyy="0.00015366"
        iyz="-7.8503E-05"
        izz="0.00034953" />
    </inertial>
    <visual>
      <origin
        xyz="0 0 0"
        rpy="0 0 0" />
      <geometry>
        <mesh
          filename="package://MRA7 - URDF2.SLDASM/meshes/6_Link.stl" />
      </geometry>
      <material
        name="">
        <color
          rgba="0.6 0.6 0.6 1" />
      </material>
    </visual>
    <collision>
      <origin
        xyz="0 0 0"
        rpy="0 0 0" />
      <geometry>
        <mesh
          filename="package://MRA7 - URDF2.SLDASM/meshes/6_Link.stl" />
      </geometry>
    </collision>
  </link>
  <joint
    name="6_Joint"
    type="revolute">
    <origin
      xyz="0 0 0"
      rpy="-1.5708 0 0" />
    <parent
      link="5_Link" />
    <child
      link="6_Link" />
    <axis
      xyz="0 0 1" />
    <limit
      lower="-2.35"
      upper="2.35"
      effort="7"
      velocity="1.57" />
    <calibration
      rising="0"
      falling="0" />
    <dynamics
      damping="0"
      friction="0" />
    <safety_controller
      soft_upper="0"
      soft_lower="0"
      k_position="0"
      k_velocity="0" />
  </joint>
  <link
    name="7_Link">
    <inertial>
      <origin
        xyz="1.1859E-05 -1.1973E-05 -0.056366"
        rpy="0 0 0" />
      <mass
        value="0.2809" />
      <inertia
        ixx="0.00082528"
        ixy="1.0112E-07"
        ixz="1.1899E-07"
        iyy="0.00062696"
        iyz="-3.9127E-07"
        izz="0.00039784" />
    </inertial>
    <visual>
      <origin
        xyz="0 0 0"
        rpy="0 0 0" />
      <geometry>
        <mesh
          filename="package://MRA7 - URDF2.SLDASM/meshes/7_Link.stl" />
      </geometry>
      <material
        name="">
        <color
          rgba="0.75294 0.75294 0.75294 1" />
      </material>
    </visual>
    <collision>
      <origin
        xyz="0 0 0"
        rpy="0 0 0" />
      <geometry>
        <mesh
          filename="package://MRA7 - URDF2.SLDASM/meshes/7_Link.stl" />
      </geometry>
    </collision>
  </link>
  <joint
    name="7_Joint"
    type="revolute">
    <origin
      xyz="0 -0.232 0"
      rpy="1.5708 0 0" />
    <parent
      link="6_Link" />
    <child
      link="7_Link" />
    <axis
      xyz="0 0 1" />
    <limit
      lower="-3.14"
      upper="3.14"
      effort="7"
      velocity="1.57" />
    <calibration
      rising="0"
      falling="0" />
    <dynamics
      damping="0"
      friction="0" />
    <safety_controller
      soft_upper="0"
      soft_lower="0"
      k_position="0"
      k_velocity="0" />
  </joint>
</robot>